<robot xmlns:xacro="http://www.ros.org/wiki/xacro" name="milestone2_robot">

<xacro:include filename="$(find milestone2_robot)/urdf/robot.gazebo"/>
<xacro:include filename="$(find milestone2_robot)/urdf/lidar_mpu.xacro"/>
<xacro:include filename="$(find milestone2_robot)/urdf/ultrasonic.xacro"/>
  <link
    name="base_link">
    <inertial>
      <origin
        xyz="-0.0185551553604413 8.98921448433398E-06 -0.00732007406833168"
        rpy="0 0 0" />
      <mass
        value="0.32673937885095" />
      <inertia
        ixx="0.00128436380730563"
        ixy="5.22949659393556E-07"
        ixz="2.88323337445004E-06"
        iyy="0.00199506204789055"
        iyz="-4.28094806808404E-08"
        izz="0.00324543983807175" />
    </inertial>
    <visual>
      <origin
        xyz="0 0 0"
        rpy="0 0 0" />
      <geometry>
        <mesh
          filename="package://milestone2_robot/meshes/base_link.STL" />
      </geometry>
      <material
        name="">
        <color
          rgba="0.972549019607843 0.43921568627451 0.0588235294117647 1" />
      </material>
    </visual>
    <collision>
      <origin
        xyz="0 0 0"
        rpy="0 0 0" />
      <geometry>
        <mesh
          filename="package://milestone2_robot/meshes/base_link.STL" />
      </geometry>
    </collision>
  </link>
  <link
    name="front_right">
    <inertial>
      <origin
        xyz="8.3066E-08 0.006116 -1.0191E-07"
        rpy="0 0 0" />
      <mass
        value="0.030153" />
      <inertia
        ixx="1.3543E-05"
        ixy="-2.1848E-10"
        ixz="7.5064E-11"
        iyy="2.2528E-05"
        iyz="-3.1083E-10"
        izz="1.3543E-05" />
    </inertial>
    <visual>
      <origin
        xyz="0 0 0"
        rpy="0 0 0" />
      <geometry>
        <mesh
          filename="package://milestone2_robot/meshes/front_right.STL" />
      </geometry>
      <material
        name="">
        <color
          rgba="0.79216 0.81961 0.93333 1" />
      </material>
    </visual>
    <collision>
      <origin
        xyz="0 0 0"
        rpy="0 0 0" />
      <geometry>
        <mesh
          filename="package://milestone2_robot/meshes/front_right.STL" />
      </geometry>
    </collision>
  </link>
  <joint
    name="front_right_joint"
    type="continuous">
    <origin
      xyz="0.061391 -0.12147 -0.015218"
      rpy="0 0 0" />
    <parent
      link="base_link" />
    <child
      link="front_right" />
    <axis
      xyz="0 1 0" />
  </joint>
  <link
    name="front_left">
    <inertial>
      <origin
        xyz="-1.1259E-07 -0.006116 6.8694E-08"
        rpy="0 0 0" />
      <mass
        value="0.030153" />
      <inertia
        ixx="1.3543E-05"
        ixy="2.774E-10"
        ixz="7.9895E-11"
        iyy="2.2528E-05"
        iyz="2.5952E-10"
        izz="1.3543E-05" />
    </inertial>
    <visual>
      <origin
        xyz="0 0 0"
        rpy="0 0 0" />
      <geometry>
        <mesh
          filename="package://milestone2_robot/meshes/front_left.STL" />
      </geometry>
      <material
        name="">
        <color
          rgba="0.79216 0.81961 0.93333 1" />
      </material>
    </visual>
    <collision>
      <origin
        xyz="0 0 0"
        rpy="0 0 0" />
      <geometry>
        <mesh
          filename="package://milestone2_robot/meshes/front_left.STL" />
      </geometry>
    </collision>
  </link>
  <joint
    name="front_left_joint"
    type="continuous">
    <origin
      xyz="0.061371 0.12143 -0.0152"
      rpy="0 0 0" />
    <parent
      link="base_link" />
    <child
      link="front_left" />
    <axis
      xyz="0 1 0" />
  </joint>
  <link
    name="rear_right">
    <inertial>
      <origin
        xyz="1.1259E-07 0.006116 6.8694E-08"
        rpy="0 0 0" />
      <mass
        value="0.030153" />
      <inertia
        ixx="1.3543E-05"
        ixy="2.774E-10"
        ixz="-7.9895E-11"
        iyy="2.2528E-05"
        iyz="-2.5952E-10"
        izz="1.3543E-05" />
    </inertial>
    <visual>
      <origin
        xyz="0 0 0"
        rpy="0 0 0" />
      <geometry>
        <mesh
          filename="package://milestone2_robot/meshes/rear_right.STL" />
      </geometry>
      <material
        name="">
        <color
          rgba="0.79216 0.81961 0.93333 1" />
      </material>
    </visual>
    <collision>
      <origin
        xyz="0 0 0"
        rpy="0 0 0" />
      <geometry>
        <mesh
          filename="package://milestone2_robot/meshes/rear_right.STL" />
      </geometry>
    </collision>
  </link>
  <joint
    name="rear_right_joint"
    type="continuous">
    <origin
      xyz="-0.094299 -0.12147 -0.0152"
      rpy="0 0 0" />
    <parent
      link="base_link" />
    <child
      link="rear_right" />
    <axis
      xyz="0 1 0" />
  </joint>
  <link
    name="rear_left">
    <inertial>
      <origin
        xyz="-8.3066E-08 -0.006116 -1.0191E-07"
        rpy="0 0 0" />
      <mass
        value="0.030153" />
      <inertia
        ixx="1.3543E-05"
        ixy="-2.1848E-10"
        ixz="-7.5064E-11"
        iyy="2.2528E-05"
        iyz="3.1083E-10"
        izz="1.3543E-05" />
    </inertial>
    <visual>
      <origin
        xyz="0 0 0"
        rpy="0 0 0" />
      <geometry>
        <mesh
          filename="package://milestone2_robot/meshes/rear_left.STL" />
      </geometry>
      <material
        name="">
        <color
          rgba="0.79216 0.81961 0.93333 1" />
      </material>
    </visual>
    <collision>
      <origin
        xyz="0 0 0"
        rpy="0 0 0" />
      <geometry>
        <mesh
          filename="package://milestone2_robot/meshes/rear_left.STL" />
      </geometry>
    </collision>
  </link>
  <joint
    name="rear_left_joint"
    type="continuous">
    <origin
      xyz="-0.094319 0.12143 -0.015218"
      rpy="0 0 0" />
    <parent
      link="base_link" />
    <child
      link="rear_left" />
    <axis
      xyz="0 1 0" />
  </joint>

<xacro:include filename="$(find milestone2_robot)/urdf/robot.gazebo"/>
<gazebo reference="base_link">
<material>Gazebo/Orange</material>
</gazebo>
<gazebo reference="rear_left">
<material>Gazebo/Black</material>
</gazebo>
<gazebo reference="rear_right">
<material>Gazebo/Black</material>
</gazebo>
<gazebo reference="front_left">
<material>Gazebo/Black</material>
</gazebo>
<gazebo reference="front_right">
<material>Gazebo/Black</material>
</gazebo>
</robot>