<?xml version="1.0" encoding="utf-8"?>
<!-- This URDF was automatically created by SolidWorks to URDF Exporter! Originally created by Stephen Brawner (brawner@gmail.com) 
     Commit Version: 1.6.0-4-g7f85cfe  Build Version: 1.6.7995.38578
     For more information, please see http://wiki.ros.org/sw_urdf_exporter -->
<robot
  name="milestone2_robot">
  <link
    name="base_link">
    <inertial>
      <origin
        xyz="-0.0185551553604413 8.98921448433398E-06 -0.00732007406833168"
        rpy="0 0 0" />
      <mass
        value="0.32673937885095" />
      <inertia
        ixx="0.00128436380730563"
        ixy="5.22949659393556E-07"
        ixz="2.88323337445004E-06"
        iyy="0.00199506204789055"
        iyz="-4.28094806808404E-08"
        izz="0.00324543983807175" />
    </inertial>
    <visual>
      <origin
        xyz="0 0 0"
        rpy="0 0 0" />
      <geometry>
        <mesh
          filename="package://milestone2_robot/meshes/base_link.STL" />
      </geometry>
      <material
        name="">
        <color
          rgba="0.972549019607843 0.43921568627451 0.0588235294117647 1" />
      </material>
    </visual>
    <collision>
      <origin
        xyz="0 0 0"
        rpy="0 0 0" />
      <geometry>
        <mesh
          filename="package://milestone2_robot/meshes/base_link.STL" />
      </geometry>
    </collision>
  </link>
  <link
    name="front_right">
    <inertial>
      <origin
        xyz="8.3066E-08 0.006116 -1.0191E-07"
        rpy="0 0 0" />
      <mass
        value="0.030153" />
      <inertia
        ixx="1.3543E-05"
        ixy="-2.1848E-10"
        ixz="7.5064E-11"
        iyy="2.2528E-05"
        iyz="-3.1083E-10"
        izz="1.3543E-05" />
    </inertial>
    <visual>
      <origin
        xyz="0 0 0"
        rpy="0 0 0" />
      <geometry>
        <mesh
          filename="package://milestone2_robot/meshes/front_right.STL" />
      </geometry>
      <material
        name="">
        <color
          rgba="0.79216 0.81961 0.93333 1" />
      </material>
    </visual>
    <collision>
      <origin
        xyz="0 0 0"
        rpy="0 0 0" />
      <geometry>
        <mesh
          filename="package://milestone2_robot/meshes/front_right.STL" />
      </geometry>
    </collision>
  </link>
  <joint
    name="front_right_joint"
    type="continuous">
    <origin
      xyz="0.061391 -0.12147 -0.015218"
      rpy="0 0 0" />
    <parent
      link="base_link" />
    <child
      link="front_right" />
    <axis
      xyz="0 -1 0" />
  </joint>
  <link
    name="front_left">
    <inertial>
      <origin
        xyz="-1.1259E-07 -0.006116 6.8694E-08"
        rpy="0 0 0" />
      <mass
        value="0.030153" />
      <inertia
        ixx="1.3543E-05"
        ixy="2.774E-10"
        ixz="7.9895E-11"
        iyy="2.2528E-05"
        iyz="2.5952E-10"
        izz="1.3543E-05" />
    </inertial>
    <visual>
      <origin
        xyz="0 0 0"
        rpy="0 0 0" />
      <geometry>
        <mesh
          filename="package://milestone2_robot/meshes/front_left.STL" />
      </geometry>
      <material
        name="">
        <color
          rgba="0.79216 0.81961 0.93333 1" />
      </material>
    </visual>
    <collision>
      <origin
        xyz="0 0 0"
        rpy="0 0 0" />
      <geometry>
        <mesh
          filename="package://milestone2_robot/meshes/front_left.STL" />
      </geometry>
    </collision>
  </link>
  <joint
    name="front_left_joint"
    type="continuous">
    <origin
      xyz="0.061371 0.12143 -0.0152"
      rpy="0 0 0" />
    <parent
      link="base_link" />
    <child
      link="front_left" />
    <axis
      xyz="0 1 0" />
  </joint>
  <link
    name="rear_right">
    <inertial>
      <origin
        xyz="1.1259E-07 0.006116 6.8694E-08"
        rpy="0 0 0" />
      <mass
        value="0.030153" />
      <inertia
        ixx="1.3543E-05"
        ixy="2.774E-10"
        ixz="-7.9895E-11"
        iyy="2.2528E-05"
        iyz="-2.5952E-10"
        izz="1.3543E-05" />
    </inertial>
    <visual>
      <origin
        xyz="0 0 0"
        rpy="0 0 0" />
      <geometry>
        <mesh
          filename="package://milestone2_robot/meshes/rear_right.STL" />
      </geometry>
      <material
        name="">
        <color
          rgba="0.79216 0.81961 0.93333 1" />
      </material>
    </visual>
    <collision>
      <origin
        xyz="0 0 0"
        rpy="0 0 0" />
      <geometry>
        <mesh
          filename="package://milestone2_robot/meshes/rear_right.STL" />
      </geometry>
    </collision>
  </link>
  <joint
    name="rear_right_joint"
    type="continuous">
    <origin
      xyz="-0.094299 -0.12147 -0.0152"
      rpy="0 0 0" />
    <parent
      link="base_link" />
    <child
      link="rear_right" />
    <axis
      xyz="0 -1 0" />
  </joint>
  <link
    name="rear_left">
    <inertial>
      <origin
        xyz="-8.3066E-08 -0.006116 -1.0191E-07"
        rpy="0 0 0" />
      <mass
        value="0.030153" />
      <inertia
        ixx="1.3543E-05"
        ixy="-2.1848E-10"
        ixz="-7.5064E-11"
        iyy="2.2528E-05"
        iyz="3.1083E-10"
        izz="1.3543E-05" />
    </inertial>
    <visual>
      <origin
        xyz="0 0 0"
        rpy="0 0 0" />
      <geometry>
        <mesh
          filename="package://milestone2_robot/meshes/rear_left.STL" />
      </geometry>
      <material
        name="">
        <color
          rgba="0.79216 0.81961 0.93333 1" />
      </material>
    </visual>
    <collision>
      <origin
        xyz="0 0 0"
        rpy="0 0 0" />
      <geometry>
        <mesh
          filename="package://milestone2_robot/meshes/rear_left.STL" />
      </geometry>
    </collision>
  </link>
  <joint
    name="rear_left_joint"
    type="continuous">
    <origin
      xyz="-0.094319 0.12143 -0.015218"
      rpy="0 0 0" />
    <parent
      link="base_link" />
    <child
      link="rear_left" />
    <axis
      xyz="0 1 0" />
  </joint>
  <link
    name="lidar">
    <inertial>
      <origin
        xyz="-0.027757 0.00015412 -0.012215"
        rpy="0 0 0" />
      <mass
        value="0.16307" />
      <inertia
        ixx="6.0761E-05"
        ixy="2.7477E-08"
        ixz="-2.4121E-07"
        iyy="6.0402E-05"
        iyz="-6.2651E-09"
        izz="0.00010759" />
    </inertial>
    <visual>
      <origin
        xyz="0 0 0"
        rpy="0 0 0" />
      <geometry>
        <mesh
          filename="package://milestone2_robot/meshes/lidar.STL" />
      </geometry>
      <material
        name="">
        <color
          rgba="0.79216 0.81961 0.93333 1" />
      </material>
    </visual>
    <collision>
      <origin
        xyz="0 0 0"
        rpy="0 0 0" />
      <geometry>
        <mesh
          filename="package://milestone2_robot/meshes/lidar.STL" />
      </geometry>
    </collision>
  </link>
  <joint
    name="lidar_joint"
    type="fixed">
    <origin
      xyz="0.079475 -0.0001912 0.043042"
      rpy="0 0 0" />
    <parent
      link="base_link" />
    <child
      link="lidar" />
    <axis
      xyz="0 0 0" />
  </joint>
  <link
    name="mpu">
    <inertial>
      <origin
        xyz="-0.00033795 -0.0002439 -0.0013042"
        rpy="0 0 0" />
      <mass
        value="0.00035125" />
      <inertia
        ixx="9.4569E-09"
        ixy="-2.6879E-13"
        ixz="8.3436E-26"
        iyy="5.2353E-09"
        iyz="-7.9805E-26"
        izz="1.4636E-08" />
    </inertial>
    <visual>
      <origin
        xyz="0 0 0"
        rpy="0 0 0" />
      <geometry>
        <mesh
          filename="package://milestone2_robot/meshes/mpu.STL" />
      </geometry>
      <material
        name="">
        <color
          rgba="0.96471 0.96471 0.95294 1" />
      </material>
    </visual>
    <collision>
      <origin
        xyz="0 0 0"
        rpy="0 0 0" />
      <geometry>
        <mesh
          filename="package://milestone2_robot/meshes/mpu.STL" />
      </geometry>
    </collision>
  </link>
  <joint
    name="mpu_joint"
    type="fixed">
    <origin
      xyz="-0.016366 6.8363E-05 0.014742"
      rpy="0 0 0" />
    <parent
      link="base_link" />
    <child
      link="mpu" />
    <axis
      xyz="0 0 0" />
  </joint>
  <link
    name="ultrasonic_front">
    <inertial>
      <origin
        xyz="-0.0071307 0.012957 -5.3951E-06"
        rpy="0 0 0" />
      <mass
        value="0.0062754" />
      <inertia
        ixx="4.6748E-07"
        ixy="-3.2911E-10"
        ixz="-1.9465E-09"
        iyy="1.7872E-07"
        iyz="-7.2811E-11"
        izz="3.903E-07" />
    </inertial>
    <visual>
      <origin
        xyz="0 0 0"
        rpy="0 0 0" />
      <geometry>
        <mesh
          filename="package://milestone2_robot/meshes/ultrasonic_front.STL" />
      </geometry>
      <material
        name="">
        <color
          rgba="0.79216 0.81961 0.93333 1" />
      </material>
    </visual>
    <collision>
      <origin
        xyz="0 0 0"
        rpy="0 0 0" />
      <geometry>
        <mesh
          filename="package://milestone2_robot/meshes/ultrasonic_front.STL" />
      </geometry>
    </collision>
  </link>
  <joint
    name="ultrasonic_front_joint"
    type="fixed">
    <origin
      xyz="0.10754 -0.013018 -0.0057577"
      rpy="0 0 0" />
    <parent
      link="base_link" />
    <child
      link="ultrasonic_front" />
    <axis
      xyz="0 0 0" />
  </joint>
  <link
    name="ultrasonic_right">
    <inertial>
      <origin
        xyz="0.012957 0.0071307 -5.3951E-06"
        rpy="0 0 0" />
      <mass
        value="0.0062754" />
      <inertia
        ixx="1.7872E-07"
        ixy="3.2911E-10"
        ixz="-7.2811E-11"
        iyy="4.6748E-07"
        iyz="1.9465E-09"
        izz="3.903E-07" />
    </inertial>
    <visual>
      <origin
        xyz="0 0 0"
        rpy="0 0 0" />
      <geometry>
        <mesh
          filename="package://milestone2_robot/meshes/ultrasonic_right.STL" />
      </geometry>
      <material
        name="">
        <color
          rgba="0.79216 0.81961 0.93333 1" />
      </material>
    </visual>
    <collision>
      <origin
        xyz="0 0 0"
        rpy="0 0 0" />
      <geometry>
        <mesh
          filename="package://milestone2_robot/meshes/ultrasonic_right.STL" />
      </geometry>
    </collision>
  </link>
  <joint
    name="ultrasonic_right_joint"
    type="fixed">
    <origin
      xyz="-0.029464 -0.10902 -0.0057577"
      rpy="0 0 0" />
    <parent
      link="base_link" />
    <child
      link="ultrasonic_right" />
    <axis
      xyz="0 0 0" />
  </joint>
  <link
    name="ultrasonic_left">
    <inertial>
      <origin
        xyz="0.013043 -0.0071307 -5.3951E-06"
        rpy="0 0 0" />
      <mass
        value="0.0062754" />
      <inertia
        ixx="1.7872E-07"
        ixy="3.2911E-10"
        ixz="7.2811E-11"
        iyy="4.6748E-07"
        iyz="-1.9465E-09"
        izz="3.903E-07" />
    </inertial>
    <visual>
      <origin
        xyz="0 0 0"
        rpy="0 0 0" />
      <geometry>
        <mesh
          filename="package://milestone2_robot/meshes/ultrasonic_left.STL" />
      </geometry>
      <material
        name="">
        <color
          rgba="0.79216 0.81961 0.93333 1" />
      </material>
    </visual>
    <collision>
      <origin
        xyz="0 0 0"
        rpy="0 0 0" />
      <geometry>
        <mesh
          filename="package://milestone2_robot/meshes/ultrasonic_left.STL" />
      </geometry>
    </collision>
  </link>
  <joint
    name="ultrasonic_left_joint"
    type="fixed">
    <origin
      xyz="-0.029464 0.10898 -0.0057577"
      rpy="0 0 0" />
    <parent
      link="base_link" />
    <child
      link="ultrasonic_left" />
    <axis
      xyz="0 0 0" />
  </joint>
 
</robot>
